<?xml version="1.0" encoding="utf-8"?>
<!-- This URDF was automatically created by SolidWorks to URDF Exporter! Originally created by Stephen Brawner (brawner@gmail.com) 
     Commit Version: 1.6.0-4-g7f85cfe  Build Version: 1.6.7995.38578
     For more information, please see http://wiki.ros.org/sw_urdf_exporter -->
<robot
  name="kuka">
  <link
    name="base_link">
    <inertial>
      <origin
        xyz="-0.080585 0.086754 -0.00067592"
        rpy="0 0 0" />
      <mass
        value="30.385" />
      <inertia
        ixx="0.38941"
        ixy="0.060696"
        ixz="-0.0047083"
        iyy="1.0819"
        iyz="0.00029206"
        izz="0.87424" />
    </inertial>
    <visual>
      <origin
        xyz="0 0 0"
        rpy="0 0 0" />
      <geometry>
        <mesh
          filename="package://kuka/meshes/base_link.STL" />
      </geometry>
      <material
        name="">
        <color
          rgba="0.79216 0.81961 0.93333 1" />
      </material>
    </visual>
    <collision>
      <origin
        xyz="0 0 0"
        rpy="0 0 0" />
      <geometry>
        <mesh
          filename="package://kuka/meshes/base_link.STL" />
      </geometry>
    </collision>
  </link>
  <link
    name="link_1">
    <inertial>
      <origin
        xyz="0.040209 0.031506 0.27673"
        rpy="0 0 0" />
      <mass
        value="67.108" />
      <inertia
        ixx="1.7966"
        ixy="0.021566"
        ixz="-0.52518"
        iyy="2.2102"
        iyz="-0.032021"
        izz="1.3812" />
    </inertial>
    <visual>
      <origin
        xyz="0 0 0"
        rpy="0 0 0" />
      <geometry>
        <mesh
          filename="package://kuka/meshes/link_1.STL" />
      </geometry>
      <material
        name="">
        <color
          rgba="0.79216 0.81961 0.93333 1" />
      </material>
    </visual>
    <collision>
      <origin
        xyz="0 0 0"
        rpy="0 0 0" />
      <geometry>
        <mesh
          filename="package://kuka/meshes/link_1.STL" />
      </geometry>
    </collision>
  </link>
  <joint
    name="joint_1"
    type="continuous">
    <origin
      xyz="0 0 0.17"
      rpy="0 0 0" />
    <parent
      link="base_link" />
    <child
      link="link_1" />
    <axis
      xyz="0 0 1" />
  </joint>
  <link
    name="link_2">
    <inertial>
      <origin
        xyz="0.0040253 -0.17424 0.57896"
        rpy="0 0 0" />
      <mass
        value="35.594" />
      <inertia
        ixx="4.4766"
        ixy="-0.0020345"
        ixz="0.076986"
        iyy="4.4996"
        iyz="0.21428"
        izz="0.23862" />
    </inertial>
    <visual>
      <origin
        xyz="0 0 0"
        rpy="0 0 0" />
      <geometry>
        <mesh
          filename="package://kuka/meshes/link_2.STL" />
      </geometry>
      <material
        name="">
        <color
          rgba="0.79216 0.81961 0.93333 1" />
      </material>
    </visual>
    <collision>
      <origin
        xyz="0 0 0"
        rpy="0 0 0" />
      <geometry>
        <mesh
          filename="package://kuka/meshes/link_2.STL" />
      </geometry>
    </collision>
  </link>
  <joint
    name="joint_2"
    type="continuous">
    <origin
      xyz="0.175 -0.078063 0.405"
      rpy="0 0 0" />
    <parent
      link="link_1" />
    <child
      link="link_2" />
    <axis
      xyz="0 1 0" />
  </joint>
  <link
    name="link_3">
    <inertial>
      <origin
        xyz="0.030518 0.10036 0.016238"
        rpy="0 0 0" />
      <mass
        value="36.678" />
      <inertia
        ixx="0.56391"
        ixy="0.064838"
        ixz="-0.082236"
        iyy="0.78687"
        iyz="0.0037993"
        izz="1.0151" />
    </inertial>
    <visual>
      <origin
        xyz="0 0 0"
        rpy="0 0 0" />
      <geometry>
        <mesh
          filename="package://kuka/meshes/link_3.STL" />
      </geometry>
      <material
        name="">
        <color
          rgba="0.79216 0.81961 0.93333 1" />
      </material>
    </visual>
    <collision>
      <origin
        xyz="0 0 0"
        rpy="0 0 0" />
      <geometry>
        <mesh
          filename="package://kuka/meshes/link_3.STL" />
      </geometry>
    </collision>
  </link>
  <joint
    name="joint_3"
    type="continuous">
    <origin
      xyz="0 0 1.29"
      rpy="0 0 0" />
    <parent
      link="link_2" />
    <child
      link="link_3" />
    <axis
      xyz="0 1 0" />
  </joint>
  <link
    name="link_4">
    <inertial>
      <origin
        xyz="0.40015 0.028052 -5.9657E-05"
        rpy="0 0 0" />
      <mass
        value="15.154" />
      <inertia
        ixx="0.070104"
        ixy="-0.099008"
        ixz="0.00018419"
        iyy="0.72993"
        iyz="-2.6085E-05"
        izz="0.7484" />
    </inertial>
    <visual>
      <origin
        xyz="0 0 0"
        rpy="0 0 0" />
      <geometry>
        <mesh
          filename="package://kuka/meshes/link_4.STL" />
      </geometry>
      <material
        name="">
        <color
          rgba="0.79216 0.81961 0.93333 1" />
      </material>
    </visual>
    <collision>
      <origin
        xyz="0 0 0"
        rpy="0 0 0" />
      <geometry>
        <mesh
          filename="package://kuka/meshes/link_4.STL" />
      </geometry>
    </collision>
  </link>
  <joint
    name="joint_4"
    type="continuous">
    <origin
      xyz="0.3268 0.078063 0.05"
      rpy="0 0 0" />
    <parent
      link="link_3" />
    <child
      link="link_4" />
    <axis
      xyz="1 0 0" />
  </joint>
  <link
    name="link_5">
    <inertial>
      <origin
        xyz="0.034814 -0.033368 -7.7896E-05"
        rpy="0 0 0" />
      <mass
        value="5.175" />
      <inertia
        ixx="0.019895"
        ixy="-0.0037956"
        ixz="-3.1227E-05"
        iyy="0.032542"
        iyz="2.0422E-05"
        izz="0.033448" />
    </inertial>
    <visual>
      <origin
        xyz="0 0 0"
        rpy="0 0 0" />
      <geometry>
        <mesh
          filename="package://kuka/meshes/link_5.STL" />
      </geometry>
      <material
        name="">
        <color
          rgba="0.79216 0.81961 0.93333 1" />
      </material>
    </visual>
    <collision>
      <origin
        xyz="0 0 0"
        rpy="0 0 0" />
      <geometry>
        <mesh
          filename="package://kuka/meshes/link_5.STL" />
      </geometry>
    </collision>
  </link>
  <joint
    name="joint_5"
    type="continuous">
    <origin
      xyz="0.7082 0 0"
      rpy="0 0 0" />
    <parent
      link="link_4" />
    <child
      link="link_5" />
    <axis
      xyz="0 1 0" />
  </joint>
  <link
    name="link_6">
    <inertial>
      <origin
        xyz="0.021433 -2.9716E-06 -4.1515E-05"
        rpy="0 0 0" />
      <mass
        value="0.36297" />
      <inertia
        ixx="0.00080922"
        ixy="9.9703E-10"
        ixz="2.4184E-07"
        iyy="0.00044078"
        iyz="1.1575E-07"
        izz="0.00044169" />
    </inertial>
    <visual>
      <origin
        xyz="0 0 0"
        rpy="0 0 0" />
      <geometry>
        <mesh
          filename="package://kuka/meshes/link_6.STL" />
      </geometry>
      <material
        name="">
        <color
          rgba="0.79216 0.81961 0.93333 1" />
      </material>
    </visual>
    <collision>
      <origin
        xyz="0 0 0"
        rpy="0 0 0" />
      <geometry>
        <mesh
          filename="package://kuka/meshes/link_6.STL" />
      </geometry>
    </collision>
  </link>
  <joint
    name="joint_6"
    type="continuous">
    <origin
      xyz="0.145 0 0"
      rpy="0 0 0" />
    <parent
      link="link_5" />
    <child
      link="link_6" />
    <axis
      xyz="1 0 0" />
  </joint>
</robot>